<?xml version="1.0"?>
<robot name="two_wheel_robot">

  <link name="base_link">
    <inertial>
      <origin xyz="0 0 0"/>
      <mass value="3.0"/>
      <inertia ixx="0.02" ixy="0.0" ixz="0.0" iyy="0.02" iyz="0.0" izz="0.03"/>
    </inertial> 
    <visual>
      <geometry>
        <box size="0.3 0.2 0.1"/>
      </geometry>
    </visual>
    <collision>
      <geometry>
        <box size="0.3 0.2 0.1"/>
      </geometry>
    </collision>
  </link>

  <link name="left_wheel">
    <inertial>
      <origin xyz="0 0 0"/>
      <mass value="0.3"/>
      <inertia ixx="0.0005" ixy="0.0" ixz="0.0" iyy="0.0005" iyz="0.0" izz="0.0005"/>
    </inertial> 
    <visual>
      <origin rpy="1.5707 0 0"/>
      <geometry>
        <cylinder radius="0.05" length="0.02"/>
      </geometry>
    </visual>
    <collision>
      <origin rpy="1.5707 0 0"/>
      <geometry>
        <cylinder radius="0.05" length="0.02"/>
      </geometry>
    </collision>
  </link>

  <link name="right_wheel">
    <inertial>
      <origin xyz="0 0 0"/>
      <mass value="0.3"/>
      <inertia ixx="0.0005" ixy="0.0" ixz="0.0" iyy="0.0005" iyz="0.0" izz="0.0005"/>
    </inertial> 
    <visual>
      <origin rpy="1.5707 0 0"/>
      <geometry>
        <cylinder radius="0.05" length="0.02"/>
      </geometry>
    </visual>
    <collision>
      <origin rpy="1.5707 0 0"/>
      <geometry>
        <cylinder radius="0.05" length="0.02"/>
      </geometry>
    </collision>
  </link>

  <link name="caster_wheel">
    <inertial>
      <origin xyz="0 0 0"/>
      <mass value="0.1"/>
      <inertia ixx="0.0002" ixy="0.0" ixz="0.0" iyy="0.0002" iyz="0.0" izz="0.0002"/>
    </inertial> 
    <visual>
      <geometry>
        <sphere radius="0.05"/>
      </geometry>
    </visual>
    <collision>
      <geometry>
        <sphere radius="0.05"/>
      </geometry>
    </collision>
  </link>

  <joint name="left_wheel_joint" type="continuous">
    <parent link="base_link"/>
    <child link="left_wheel"/>
    <origin xyz="0.1 0.1 -0.05"/>
    <axis xyz="0 1 0"/>
  </joint>

  <joint name="right_wheel_joint" type="continuous">
    <parent link="base_link"/>
    <child link="right_wheel"/>
    <origin xyz="0.1 -0.1 -0.05"/>
    <axis xyz="0 1 0"/>
  </joint>

  <joint name="caster_joint" type="fixed">
    <parent link="base_link"/>
    <child link="caster_wheel"/>
    <origin xyz="-0.1 0 -0.05"/>
  </joint>

  <link name="lidar_link">
    <inertial>
      <origin xyz="0 0 0"/>
      <mass value="0.1"/>
      <inertia ixx="0.0001" ixy="0.0" ixz="0.0" iyy="0.0001" iyz="0.0" izz="0.0001"/>
    </inertial>
    <visual>
      <geometry>
        <cylinder radius="0.04" length="0.04"/>
      </geometry>
      <material name="red">
        <color rgba="1.0 0.0 0.0 1.0"/>
      </material>
    </visual>
    </link>

  <joint name="lidar_joint" type="revolute">
    <parent link="base_link"/>
    <child link="lidar_link"/>
    <origin xyz="0 0 0.07"/>
    <axis xyz="0 0 1"/>
    <limit lower="0" upper="0" effort="0" velocity="0"/>
  </joint>

  <link name="camera_link">
    <visual>
      <geometry>
        <box size="0.02 0.05 0.02"/>
      </geometry>
      <material name="blue">
        <color rgba="0.0 0.0 1.0 1.0"/>
      </material>
    </visual>
    </link>

  <joint name="camera_joint" type="fixed">
    <parent link="base_link"/>
    <child link="camera_link"/>
    <origin xyz="0.15 0 0.05" rpy="0 0 0"/> </joint>

  <gazebo reference="lidar_joint">
    <preserveFixedJoint>true</preserveFixedJoint>
  </gazebo>

  <gazebo>
    <plugin filename="libgz-sim8-diff-drive-system.so"
            name="gz::sim::systems::DiffDrive">
      <left_joint>left_wheel_joint</left_joint>
      <right_joint>right_wheel_joint</right_joint>
      <wheel_separation>0.2</wheel_separation>
      <wheel_radius>0.05</wheel_radius>
      <topic>cmd_vel</topic>
    </plugin>
  </gazebo>

  <gazebo reference="caster_wheel">
    <mu1>0.0</mu1>
    <mu2>0.0</mu2>
  </gazebo>

  <gazebo reference="lidar_link">
    <sensor name="lidar_sensor" type="gpu_lidar"> 
      <pose>0 0 0 0 0 0</pose> <always_on>true</always_on>
      <visualize>true</visualize> <update_rate>10</update_rate>
      <topic>/scan</topic>
      <gz_frame_id>lidar_link</gz_frame_id>
      <lidar>
        <scan>
          <horizontal>
            <samples>360</samples>
            <resolution>1.0</resolution>
            <min_angle>-3.14159</min_angle>
            <max_angle>3.14159</max_angle>
          </horizontal>
        </scan>
        <range>
          <min>0.12</min>
          <max>10.0</max>
          <resolution>0.01</resolution>
        </range>
      </lidar>
    </sensor>
  </gazebo>

  <gazebo reference="camera_link">
    <sensor name="camera_sensor" type="camera">
      <pose>0 0 0 0 0 0</pose>
      <always_on>true</always_on>
      <update_rate>30</update_rate>
      <visualize>true</visualize>
      <topic>/camera/image_raw</topic>
      <gz_frame_id>camera_link</gz_frame_id>
      <camera name="intel_arc_cam">
        <horizontal_fov>1.089</horizontal_fov> <image>
          <width>640</width>
          <height>480</height>
          <format>R8G8B8</format>
        </image>
        <clip>
          <near>0.05</near>
          <far>8.0</far>
        </clip>
      </camera>
    </sensor>
  </gazebo>

</robot>